Workbook

Sheet Golden Set
A1: Team 8 golden test set: final labels
A2: 180 tickets from rows 8000-8999, labelled independently by two team members (Hakim & Glenn) and reconciled under the labelling protocol . Every final label is a live formula: a Resolution Log decision if the labellers disagreed; otherwise the Consistency Check label if the agreed label was changed; otherwise the agreed label.
A4: row_id | B4: Labeler 1 | C4: Labeler 2 | D4: Final label | E4: Source of final label | F4: Differs from Labeler 1 | G4: Differs from Labeler 2
A5: 8022 | B5: =INDEX('Labeler 1'!$C$2:$C$181,MATCH(A5,'Labeler 1'!$A$2:$A$181,0)) -> Credit reporting | C5: =INDEX('Labeler 2'!$C$2:$C$181,MATCH(A5,'Labeler 2'!$A$2:$A$181,0)) -> Credit reporting | D5: =IF(COUNTIF('Resolution Log'!$A$5:$A$24,A5)>0,INDEX('Resolution Log'!$G$5:$G$24,MATCH(A5,'Resolution Log'!$A$5:$A$24,0)),IF(COUNTIFS('Consistency Check'!$A$5:$A$99,A5,'Consistency Check'!$D$5:$D$99,"No")>0,INDEX('Consistency Check'!$E$5:$E$99,MATCH(A5,'Consistency Check'!$A$5:$A$99,0)),C5)) -> Credit reporting | E5: =IF(COUNTIF('Resolution Log'!$A$5:$A$24,A5)>0,"Resolution Log (disagreement)",IF(COUNTIFS('Consistency Check'!$A$5:$A$99,A5,'Consistency Check'!$D$5:$D$99,"No")>0,"Consistency Check (agreed label changed)",IF(COUNTIF('Consistency Check'!$A$5:$A$99,A5)>0,"Consistency Check (agreed label confirmed)","Agreed label"))) -> Agreed label | F5: =IF(D5<>B5,"Yes","") | G5: =IF(D5<>C5,"Yes","")
A6: 8024 | B6: =INDEX('Labeler 1'!$C$2:$C$181,MATCH(A6,'Labeler 1'!$A$2:$A$181,0)) -> Money transfer or service | C6: =INDEX('Labeler 2'!$C$2:$C$181,MATCH(A6,'Labeler 2'!$A$2:$A$181,0)) -> Money transfer or service | D6: =IF(COUNTIF('Resolution Log'!$A$5:$A$24,A6)>0,INDEX('Resolution Log'!$G$5:$G$24,MATCH(A6,'Resolution Log'!$A$5:$A$24,0)),IF(COUNTIFS('Consistency Check'!$A$5:$A$99,A6,'Consistency Check'!$D$5:$D$99,"No")>0,INDEX('Consistency Check'!$E$5:$E$99,MATCH(A6,'Consistency Check'!$A$5:$A$99,0)),C6)) -> Money transfer or service | E6: =IF(COUNTIF('Resolution Log'!$A$5:$A$24,A6)>0,"Resolution Log (disagreement)",IF(COUNTIFS('Consistency Check'!$A$5:$A$99,A6,'Consistency Check'!$D$5:$D$99,"No")>0,"Consistency Check (agreed label changed)",IF(COUNTIF('Consistency Check'!$A$5:$A$99,A6)>0,"Consistency Check (agreed label confirmed)","Agreed label"))) -> Consistency Check (agreed label confirmed) | F6: =IF(D6<>B6,"Yes","") | G6: =IF(D6<>C6,"Yes","")
A7: 8033 | B7: =INDEX('Labeler 1'!$C$2:$C$181,MATCH(A7,'Labeler 1'!$A$2:$A$181,0)) -> Credit card | C7: =INDEX('Labeler 2'!$C$2:$C$181,MATCH(A7,'Labeler 2'!$A$2:$A$181,0)) -> Credit card | D7: =IF(COUNTIF('Resolution Log'!$A$5:$A$24,A7)>0,INDEX('Resolution Log'!$G$5:$G$24,MATCH(A7,'Resolution Log'!$A$5:$A$24,0)),IF(COUNTIFS('Consistency Check'!$A$5:$A$99,A7,'Consistency Check'!$D$5:$D$99,"No")>0,INDEX('Consistency Check'!$E$5:$E$99,MATCH(A7,'Consistency Check'!$A$5:$A$99,0)),C7)) -> Credit card | E7: =IF(COUNTIF('Resolution Log'!$A$5:$A$24,A7)>0,"Resolution Log (disagreement)",IF(COUNTIFS('Consistency Check'!$A$5:$A$99,A7,'Consistency Check'!$D$5:$D$99,"No")>0,"Consistency Check (agreed label changed)",IF(COUNTIF('Consistency Check'!$A$5:$A$99,A7)>0,"Consistency Check (agreed label confirmed)","Agreed label"))) -> Agreed label | F7: =IF(D7<>B7,"Yes","") | G7: =IF(D7<>C7,"Yes","")
A8: 8044 | B8: =INDEX('Labeler 1'!$C$2:$C$181,MATCH(A8,'Labeler 1'!$A$2:$A$181,0)) -> Consumer loan | C8: =INDEX('Labeler 2'!$C$2:$C$181,MATCH(A8,'Labeler 2'!$A$2:$A$181,0)) -> Consumer loan | D8: =IF(COUNTIF('Resolution Log'!$A$5:$A$24,A8)>0,INDEX('Resolution Log'!$G$5:$G$24,MATCH(A8,'Resolution Log'!$A$5:$A$24,0)),IF(COUNTIFS('Consistency Check'!$A$5:$A$99,A8,'Consistency Check'!$D$5:$D$99,"No")>0,INDEX('Consistency Check'!$E$5:$E$99,MATCH(A8,'Consistency Check'!$A$5:$A$99,0)),C8)) -> Consumer loan | E8: =IF(COUNTIF('Resolution Log'!$A$5:$A$24,A8)>0,"Resolution Log (disagreement)",IF(COUNTIFS('Consistency Check'!$A$5:$A$99,A8,'Consistency Check'!$D$5:$D$99,"No")>0,"Consistency Check (agreed label changed)",IF(COUNTIF('Consistency Check'!$A$5:$A$99,A8)>0,"Consistency Check (agreed label confirmed)","Agreed label"))) -> Consistency Check (agreed label confirmed) | F8: =IF(D8<>B8,"Yes","") | G8: =IF(D8<>C8,"Yes","")
A9: 8050 | B9: =INDEX('Labeler 1'!$C$2:$C$181,MATCH(A9,'Labeler 1'!$A$2:$A$181,0)) -> Debt collection | C9: =INDEX('Labeler 2'!$C$2:$C$181,MATCH(A9,'Labeler 2'!$A$2:$A$181,0)) -> Debt collection | D9: =IF(COUNTIF('Resolution Log'!$A$5:$A$24,A9)>0,INDEX('Resolution Log'!$G$5:$G$24,MATCH(A9,'Resolution Log'!$A$5:$A$24,0)),IF(COUNTIFS('Consistency Check'!$A$5:$A$99,A9,'Consistency Check'!$D$5:$D$99,"No")>0,INDEX('Consistency Check'!$E$5:$E$99,MATCH(A9,'Consistency Check'!$A$5:$A$99,0)),C9)) -> Debt collection | E9: =IF(COUNTIF('Resolution Log'!$A$5:$A$24,A9)>0,"Resolution Log (disagreement)",IF(COUNTIFS('Consistency Check'!$A$5:$A$99,A9,'Consistency Check'!$D$5:$D$99,"No")>0,"Consistency Check (agreed label changed)",IF(COUNTIF('Consistency Check'!$A$5:$A$99,A9)>0,"Consistency Check (agreed label confirmed)","Agreed label"))) -> Agreed label | F9: =IF(D9<>B9,"Yes","") | G9: =IF(D9<>C9,"Yes","")
A10: 8053 | B10: =INDEX('Labeler 1'!$C$2:$C$181,MATCH(A10,'Labeler 1'!$A$2:$A$181,0)) -> Credit reporting | C10: =INDEX('Labeler 2'!$C$2:$C$181,MATCH(A10,'Labeler 2'!$A$2:$A$181,0)) -> Credit reporting | D10: =IF(COUNTIF('Resolution Log'!$A$5:$A$24,A10)>0,INDEX('Resolution Log'!$G$5:$G$24,MATCH(A10,'Resolution Log'!$A$5:$A$24,0)),IF(COUNTIFS('Consistency Check'!$A$5:$A$99,A10,'Consistency Check'!$D$5:$D$99,"No")>0,INDEX('Consistency Check'!$E$5:$E$99,MATCH(A10,'Consistency Check'!$A$5:$A$99,0)),C10)) -> Credit reporting | E10: =IF(COUNTIF('Resolution Log'!$A$5:$A$24,A10)>0,"Resolution Log (disagreement)",IF(COUNTIFS('Consistency Check'!$A$5:$A$99,A10,'Consistency Check'!$D$5:$D$99,"No")>0,"Consistency Check (agreed label changed)",IF(COUNTIF('Consistency Check'!$A$5:$A$99,A10)>0,"Consistency Check (agreed label confirmed)","Agreed label"))) -> Agreed label | F10: =IF(D10<>B10,"Yes","") | G10: =IF(D10<>C10,"Yes","")
A11: 8060 | B11: =INDEX('Labeler 1'!$C$2:$C$181,MATCH(A11,'Labeler 1'!$A$2:$A$181,0)) -> Credit reporting | C11: =INDEX('Labeler 2'!$C$2:$C$181,MATCH(A11,'Labeler 2'!$A$2:$A$181,0)) -> Credit reporting | D11: =IF(COUNTIF('Resolution Log'!$A$5:$A$24,A11)>0,INDEX('Resolution Log'!$G$5:$G$24,MATCH(A11,'Resolution Log'!$A$5:$A$24,0)),IF(COUNTIFS('Consistency Check'!$A$5:$A$99,A11,'Consistency Check'!$D$5:$D$99,"No")>0,INDEX('Consistency Check'!$E$5:$E$99,MATCH(A11,'Consistency Check'!$A$5:$A$99,0)),C11)) -> Credit reporting | E11: =IF(COUNTIF('Resolution Log'!$A$5:$A$24,A11)>0,"Resolution Log (disagreement)",IF(COUNTIFS('Consistency Check'!$A$5:$A$99,A11,'Consistency Check'!$D$5:$D$99,"No")>0,"Consistency Check (agreed label changed)",IF(COUNTIF('Consistency Check'!$A$5:$A$99,A11)>0,"Consistency Check (agreed label confirmed)","Agreed label"))) -> Agreed label | F11: =IF(D11<>B11,"Yes","") | G11: =IF(D11<>C11,"Yes","")
A12: 8062 | B12: =INDEX('Labeler 1'!$C$2:$C$181,MATCH(A12,'Labeler 1'!$A$2:$A$181,0)) -> Credit reporting | C12: =INDEX('Labeler 2'!$C$2:$C$181,MATCH(A12,'Labeler 2'!$A$2:$A$181,0)) -> Credit reporting | D12: =IF(COUNTIF('Resolution Log'!$A$5:$A$24,A12)>0,INDEX('Resolution Log'!$G$5:$G$24,MATCH(A12,'Resolution Log'!$A$5:$A$24,0)),IF(COUNTIFS('Consistency Check'!$A$5:$A$99,A12,'Consistency Check'!$D$5:$D$99,"No")>0,INDEX('Consistency Check'!$E$5:$E$99,MATCH(A12,'Consistency Check'!$A$5:$A$99,0)),C12)) -> Credit reporting | E12: =IF(COUNTIF('Resolution Log'!$A$5:$A$24,A12)>0,"Resolution Log (disagreement)",IF(COUNTIFS('Consistency Check'!$A$5:$A$99,A12,'Consistency Check'!$D$5:$D$99,"No")>0,"Consistency Check (agreed label changed)",IF(COUNTIF('Consistency Check'!$A$5:$A$99,A12)>0,"Consistency Check (agreed label confirmed)","Agreed label"))) -> Agreed label | F12: =IF(D12<>B12,"Yes","") | G12: =IF(D12<>C12,"Yes","")
A13: 8071 | B13: =INDEX('Labeler 1'!$C$2:$C$181,MATCH(A13,'Labeler 1'!$A$2:$A$181,0)) -> Credit reporting | C13: =INDEX('Labeler 2'!$C$2:$C$181,MATCH(A13,'Labeler 2'!$A$2:$A$181,0)) -> Credit reporting | D13: =IF(COUNTIF('Resolution Log'!$A$5:$A$24,A13)>0,INDEX('Resolution Log'!$G$5:$G$24,MATCH(A13,'Resolution Log'!$A$5:$A$24,0)),IF(COUNTIFS('Consistency Check'!$A$5:$A$99,A13,'Consistency Check'!$D$5:$D$99,"No")>0,INDEX('Consistency Check'!$E$5:$E$99,MATCH(A13,'Consistency Check'!$A$5:$A$99,0)),C13)) -> Credit reporting | E13: =IF(COUNTIF('Resolution Log'!$A$5:$A$24,A13)>0,"Resolution Log (disagreement)",IF(COUNTIFS('Consistency Check'!$A$5:$A$99,A13,'Consistency Check'!$D$5:$D$99,"No")>0,"Consistency Check (agreed label changed)",IF(COUNTIF('Consistency Check'!$A$5:$A$99,A13)>0,"Consistency Check (agreed label confirmed)","Agreed label"))) -> Agreed label | F13: =IF(D13<>B13,"Yes","") | G13: =IF(D13<>C13,"Yes","")
A14: 8074 | B14: =INDEX('Labeler 1'!$C$2:$C$181,MATCH(A14,'Labeler 1'!$A$2:$A$181,0)) -> Credit reporting | C14: =INDEX('Labeler 2'!$C$2:$C$181,MATCH(A14,'Labeler 2'!$A$2:$A$181,0)) -> Credit reporting | D14: =IF(COUNTIF('Resolution Log'!$A$5:$A$24,A14)>0,INDEX('Resolution Log'!$G$5:$G$24,MATCH(A14,'Resolution Log'!$A$5:$A$24,0)),IF(COUNTIFS('Consistency Check'!$A$5:$A$99,A14,'Consistency Check'!$D$5:$D$99,"No")>0,INDEX('Consistency Check'!$E$5:$E$99,MATCH(A14,'Consistency Check'!$A$5:$A$99,0)),C14)) -> Credit reporting | E14: =IF(COUNTIF('Resolution Log'!$A$5:$A$24,A14)>0,"Resolution Log (disagreement)",IF(COUNTIFS('Consistency Check'!$A$5:$A$99,A14,'Consistency Check'!$D$5:$D$99,"No")>0,"Consistency Check (agreed label changed)",IF(COUNTIF('Consistency Check'!$A$5:$A$99,A14)>0,"Consistency Check (agreed label confirmed)","Agreed label"))) -> Agreed label | F14: =IF(D14<>B14,"Yes","") | G14: =IF(D14<>C14,"Yes","")
A15: 8094 | B15: =INDEX('Labeler 1'!$C$2:$C$181,MATCH(A15,'Labeler 1'!$A$2:$A$181,0)) -> Money transfer or service | C15: =INDEX('Labeler 2'!$C$2:$C$181,MATCH(A15,'Labeler 2'!$A$2:$A$181,0)) -> Money transfer or service | D15: =IF(COUNTIF('Resolution Log'!$A$5:$A$24,A15)>0,INDEX('Resolution Log'!$G$5:$G$24,MATCH(A15,'Resolution Log'!$A$5:$A$24,0)),IF(COUNTIFS('Consistency Check'!$A$5:$A$99,A15,'Consistency Check'!$D$5:$D$99,"No")>0,INDEX('Consistency Check'!$E$5:$E$99,MATCH(A15,'Consistency Check'!$A$5:$A$99,0)),C15)) -> Money transfer or service | E15: =IF(COUNTIF('Resolution Log'!$A$5:$A$24,A15)>0,"Resolution Log (disagreement)",IF(COUNTIFS('Consistency Check'!$A$5:$A$99,A15,'Consistency Check'!$D$5:$D$99,"No")>0,"Consistency Check (agreed label changed)",IF(COUNTIF('Consistency Check'!$A$5:$A$99,A15)>0,"Consistency Check (agreed label confirmed)","Agreed label"))) -> Agreed label | F15: =IF(D15<>B15,"Yes","") | G15: =IF(D15<>C15,"Yes","")
A16: 8095 | B16: =INDEX('Labeler 1'!$C$2:$C$181,MATCH(A16,'Labeler 1'!$A$2:$A$181,0)) -> Money transfer or service | C16: =INDEX('Labeler 2'!$C$2:$C$181,MATCH(A16,'Labeler 2'!$A$2:$A$181,0)) -> Bank account or service | D16: =IF(COUNTIF('Resolution Log'!$A$5:$A$24,A16)>0,INDEX('Resolution Log'!$G$5:$G$24,MATCH(A16,'Resolution Log'!$A$5:$A$24,0)),IF(COUNTIFS('Consistency Check'!$A$5:$A$99,A16,'Consistency Check'!$D$5:$D$99,"No")>0,INDEX('Consistency Check'!$E$5:$E$99,MATCH(A16,'Consistency Check'!$A$5:$A$99,0)),C16)) -> Bank account or service | E16: =IF(COUNTIF('Resolution Log'!$A$5:$A$24,A16)>0,"Resolution Log (disagreement)",IF(COUNTIFS('Consistency Check'!$A$5:$A$99,A16,'Consistency Check'!$D$5:$D$99,"No")>0,"Consistency Check (agreed label changed)",IF(COUNTIF('Consistency Check'!$A$5:$A$99,A16)>0,"Consistency Check (agreed label confirmed)","Agreed label"))) -> Resolution Log (disagreement) | F16: =IF(D16<>B16,"Yes","") -> Yes | G16: =IF(D16<>C16,"Yes","")
... A184: 8999 | B184: =INDEX('Labeler 1'!$C$2:$C$181,MATCH(A184,'Labeler 1'!$A$2:$A$181,0)) -> Consumer loan | C184: =INDEX('Labeler 2'!$C$2:$C$181,MATCH(A184,'Labeler 2'!$A$2:$A$181,0)) -> Consumer loan | D184: =IF(COUNTIF('Resolution Log'!$A$5:$A$24,A184)>0,INDEX('Resolution Log'!$G$5:$G$24,MATCH(A184,'Resolution Log'!$A$5:$A$24,0)),IF(COUNTIFS('Consistency Check'!$A$5:$A$99,A184,'Consistency Check'!$D$5:$D$99,"No")>0,INDEX('Consistency Check'!$E$5:$E$99,MATCH(A184,'Consistency Check'!$A$5:$A$99,0)),C184)) -> Consumer loan | E184: =IF(COUNTIF('Resolution Log'!$A$5:$A$24,A184)>0,"Resolution Log (disagreement)",IF(COUNTIFS('Consistency Check'!$A$5:$A$99,A184,'Consistency Check'!$D$5:$D$99,"No")>0,"Consistency Check (agreed label changed)",IF(COUNTIF('Consistency Check'!$A$5:$A$99,A184)>0,"Consistency Check (agreed label confirmed)","Agreed label"))) -> Consistency Check (agreed label confirmed) | F184: =IF(D184<>B184,"Yes","") | G184: =IF(D184<>C184,"Yes","")
A186: Summary
A187: Rows | D187: =COUNTA(A5:A184) -> 180
A188: Final labels that are blank or invalid (should be 0) | D188: =COUNTA(A5:A184)-SUMPRODUCT(COUNTIF(D5:D184,{"Credit reporting","Debt collection","Mortgage","Credit card","Bank account or service","Consumer loan","Money transfer or service"})) -> 0
A189: Source: Resolution Log (disagreement) | D189: =COUNTIF(E5:E184,"Resolution Log*") -> 20
A190: Source: agreed label changed | D190: =COUNTIF(E5:E184,"*changed*") -> 2
A191: Source: agreed label confirmed on Consistency Check | D191: =COUNTIF(E5:E184,"*confirmed*") -> 42
A192: Source: agreed label, not affected by any rule change | D192: =COUNTIF(E5:E184,"Agreed label") -> 116
A193: Final differs from Labeler 1 | D193: =COUNTIF(F5:F184,"Yes") -> 15
A194: Final differs from Labeler 2 | D194: =COUNTIF(G5:G184,"Yes") -> 10
A195: Final differs from both labellers | D195: =COUNTIFS(F5:F184,"Yes",G5:G184,"Yes") -> 3
A197: Final label distribution
A198: Credit reporting | D198: =COUNTIF(D5:D184,A198) -> 53 | E198: =D198/D187 -> 0.29444444
A199: Debt collection | D199: =COUNTIF(D5:D184,A199) -> 16 | E199: =D199/D187 -> 0.088888889
A200: Mortgage | D200: =COUNTIF(D5:D184,A200) -> 26 | E200: =D200/D187 -> 0.14444444
A201: Credit card | D201: =COUNTIF(D5:D184,A201) -> 20 | E201: =D201/D187 -> 0.11111111
A202: Bank account or service | D202: =COUNTIF(D5:D184,A202) -> 23 | E202: =D202/D187 -> 0.12777778
A203: Consumer loan | D203: =COUNTIF(D5:D184,A203) -> 19 | E203: =D203/D187 -> 0.10555556
A204: Money transfer or service | D204: =COUNTIF(D5:D184,A204) -> 23 | E204: =D204/D187 -> 0.12777778

Sheet Protocol
A1: ICT3113 Assignment 1 -- Team 8 Labelling Protocol (V10)
A2: Golden test set: 180 tickets from rows 8000-8999, stratified proportional to raw category mix. Labelled independently by 2 team members (Hakim & Glenn), no conferring, then reconciled.
A4: Category | B4: Core scope | C4: Edge-case rule
A5: Credit reporting | B5: Errors, disputes, or investigations about what's ON a credit report/file itself (accuracy, unauthorized accounts, bureau disputes) | C5: Classify by the MAIN OUTCOME the ticket asks for, not the laws it cites. If the main demand is removing or correcting an entry on the credit report -> here, even if validation or the FDCPA is cited as the reason. When a ticket asks for both, go with the request that has actual events behind it. (rev 4)
A6: Debt collection | B6: Collection conduct by a collection agency, debt buyer, attorney, or the creditor itself (calls, harassment, threats, lawsuits, garnishment, wrong amount, validation requests) -> here. A creditor's fees, terms or account servicing -> that product's category. (rev 10) | C6: If the main demand is validation or verification of the debt itself (e.g. an itemized validation request to a collector, or disputing that the debt is owed) -> here, even if deletion from credit reports is requested as the consequence of failed validation. (rev 4)
A7: Mortgage | B7: Origination, servicing, PMI, refinancing, foreclosure on a home loan | C7: If reporting accuracy of the mortgage account is the actual complaint -> Credit reporting. Foreclosure framed as collector misconduct (e.g. false representations, improper seizure of property) -> Debt collection; problems with the foreclosure process itself (e.g. notices, loss mitigation, servicer handling) -> stays Mortgage. (rev 5)
A8: Credit card | B8: Card fees, charges, disputes, closures, rewards, APR issues | C8: Store-branded credit cards (a card used to finance purchases at a particular store, chain or dealer) -> here. (rev 7)
A9: Bank account or service | B9: Checking and savings accounts, including online banks (e.g. Chime, Marcus), and their debit cards: deposits, holds, checks, fees, closures, unauthorized access or charges (rev 3). | C9: If a real loan's payments or funds route through a bank account (e.g. loan payments debited from checking) -> Consumer loan, unless the account-level action (freeze/closure) is the actual complaint. If no loan exists (e.g. a company the customer never borrowed from takes money), the Fraud and unrecognised accounts rule applies. (rev 10) Prepaid cards fit no category -> force-fit here: the card holds the customer's own funds, like an account. (rev 7)
A10: Consumer loan | B10: Personal loans, auto loans, student loans, and their servicing | C10: A loan whose type is not named -> Consumer loan, unless a mortgage-specific term appears (e.g. escrow, PMI, foreclosure, refinance, home or property) -> Mortgage. "Servicer" alone is not a mortgage signal: mortgages, student loans and auto loans all have servicers. (rev 6) Buy-now-pay-later and point-of-sale instalment financing -> here when the complaint is about the financing itself; if the complaint is about payments a payment app actually processed, rev 3 applies. (rev 7)
A11: Money transfer or service | B11: Payment apps, digital wallets, crypto platforms, and transfer services (e.g. PayPal, Cash App, Venmo, Zelle, Coinbase, wires the customer sends, remittances such as Western Union) (rev 3). | C11: Categorize by PRODUCT, not by what went wrong: a lock, fraud, fee, or stuck payment on a payment app, wallet, or crypto platform stays here; the same problem on a bank deposit account -> Bank account or service (rev 3).
A13: General Rules
A14: Fits two categories: | B14: Classify by the financial PRODUCT that is the substance of the complaint, not the mechanism used to raise it. Use the edge-case rules above to break ties.
A15: Fits none well: | B15: Force-fit to the closest of the 7 (the service can only output one of these 7), and write a short reason in the Flag/Notes column. Do not leave the category blank.
A16: Fraud and unrecognised accounts: | B16: If the grievance is with a credit bureau, or the main demand is removal from the credit report -> Credit reporting. If the grievance is with the company holding the account (how the lender, card issuer or bank handles the fraud) -> that account's product category, even if it also appears on the credit report. Money taken from the customer's own account without authorization by someone they have no account or agreement with (a stranger, an impostor, an unknown company) -> the customer's own account decides the category (rev 3); the payee's line of business and the payment method (card, ACH, wire) do not. If the customer has an account or agreement with the company that took the money (a lender, seller, or payment app they used), that relationship decides. (rev 8)
A17: Product not stated: | B17: When the product is not stated: a dispute over a purchase from a merchant (non-delivery, overcharge, return) -> Credit card; an action by a bank on the account itself (closure, freeze) -> Bank account. This is a default for missing information, not something the text proves; do not infer the product from what a provider is known for. (rev 9)
A18: Order of application: | B18: The specific rules (category edge-case rules, Fraud and unrecognised accounts, Product not stated) take precedence over Fits two categories; Fits none well is the last resort. (rev 10)
A19: Revision log | B19: See the Revision Log tab.
A20: Heuristic scan results (run on all 180 candidates)
A21: 25 of 180 rows (~14%) flagged before labelling as likely edge cases (26 flags; one row, 8644, carried two) -- see heuristic_flag column on Labeler tabs. Pre-labelling notes; outcomes are recorded in the Revision Log.
A22: 11 rows: loan-servicer complaint with no product named (mortgage vs consumer loan). Resolved by rev 6.
A23: 7 rows: raw label Credit card but no card-related language -- check for raw mislabeling.
A24: 6 rows: both debt-collection and credit-reporting language present. Resolved by rev 4.
A25: 2 rows: loan and bank-account language both present.

Sheet Labeler 1
A1: row_id | B1: narrative | C1: your_category | D1: flag_note (if forced/hard fit/general comments)
A2: 8022 | B2: I applied for a bank account with XXXX on XXXX XXXX and was declined stating there were discrepancies on my XXXX report. I knew that had to be an error because i filed for bankruptcy and every creditor was ordered by the judge to CEASE AND DESIST. I filed chapter XXXX bankruptcy with case XXXX FL on XX/XX/17 and the case was discharged in XX/XX/2017. However, XXXX XXXX is STILL REPORTING EVEN AFTER MY BANKRUPTCY. Each creditor is subject to up to {$1000.00} fine for violation of fair credit reporting act. Chapter XXXX bankruptcy discharges all debt! | C2: Credit reporting
A3: 8024 | B3: I fell victim to a multilayered scam operation orchestrated by XXXX ( XXXX ) ( the Company ) with the design, development, manufacturing, promoting, marketing, distributing, labeling, and/or sale of illegal and outright fraudulent investment services, all of which aim at contributing to the goal of robbing and defrauding clients through a predetermined cycle of client losses to gains in the equivalent of XXXX USD which was transferred from my wallet utilizing Coinbases services. | C3: Money transfer or service
A4: 8033 | B4: I have been a longstanding customer with Chase Bank, maintaining multiple credit card accounts with them over a period of several years. I have always managed my accounts responsibly, making timely payments and adhering to all the terms and conditions. To my knowledge, I have not violated any rules or engaged in any behavior that would warrant account closure. Recently, I discovered that Chase had closed all of my credit card accounts without prior notice or explanation. I received no warning or notification regarding any issues with my accounts. Upon noticing the closures, I immediately contacted Chase customer service to inquire about the reason behind their decision. Despite multiple attempts and speaking with several representatives, Chase refused to provide any specific reason for the closures. I was told that they were unable to disclose why the accounts were closed and that the decision was final. I was not given any opportunity to appeal or resolve any potential issue that may have prompted this action. This sudden and unexplained closure of my credit card accounts has caused me significant inconvenience and concern. It has impacted my credit utilization ratio, which may negatively affect my credit score, and I am now left without access to credit that I previously relied on for regular financial activities. I believe that as a consumer in good standing, I am entitled to a clear explanation for the closure of my accounts. The lack of transparency and unwillingness to provide any justification is deeply troubling and potentially unfair. I am requesting that the CFPB investigate this matter and help facilitate a response from Chase that provides a clear and detailed explanation for their actions. | C4: Credit card
A5: 8044 | B5: My husband and I open a personal loan through OneMain. The company was originally named SpringLeaf. The loan was paid in full XXXX XXXX, 2017. I tried to obtain an letter from the company stating this loan was paid in full ; so I could provide it to the three credit bureaus ; but, was unsuccessful. Attached will be a summary printout from the local office and a statement printout providing {$0.00} balance. Even though these statements are acceptable to me ; there are not acceptable for the three credit reporting bureaus. Would you please assist me with this matter? Thank you | C5: Consumer loan | D5: The product is explicitly a personal loan; the request for payoff documentation is incidental to the loan itself, so Consumer loan applies.
A6: 8050 | B6: Cypress Collections Professional Collection Agency XX/XX/XXXX XXXX XXXX XXXX XXXX, CA XXXX Re : Reference # XXXX Client # XXXX Thank you for your inquiry. I do in fact dispute the claim of {$120.00} plus the additional interest that was erroneously billed to me and certainly, your threats to damage my credit worthiness. I am a Veteran under the care of the Veterans Administration at XXXX XXXX. I have communicated with Doctors on Duty and have told them that their claim needs to be filed with the Veterans Administration. I also told Doctors on Duty that I would talk to the VA regarding the erroneous billing for my approved office visit. I talked to my primary care doctor at the VA and was told that there is a record of an authorized request for medical service on XX/XX/XXXX. Initially I told this to Doctors on Duty bookeeper. I clearly told the Doctors on Duty staff that the VA sent me and that I needed to be evaluated for XXXX because of XXXX XXXX and that I was a veteran. The reason for this going to collection is clearly not my doing. It is in fact Doctors on Duty responsibility to bill the VA as per their contract ( a requirement that they did not do ) Embroiling me in their mishap with a threat of affecting my credit worthiness is disturbing at best. I have contacted the Community Provider division of VA and have filed an Adverse Credit Report - XXXX. Cypress Collection as well as Doctors on Duty have been notified to cease and desist their illegal claim. If in fact my credit worthiness is affected, I will sue for defamation of character and elder abuse of an ailing veteran. I am willing to pursue a course of action against both Doctors on Duty and Cypress if this persists any longer. I defended my country with dignity and courage and expect respect and thanks for my service, rather than being threatened and abused by Doctors on Duty and Cypress Collections. Thank You XXXX cc : FTC www.ftc.gov cc : Senator XXXX XXXX | C6: Debt collection | D6: Both collection and reporting language appear, but the complaint centers on the collector's billing/threats and cease-and-desist demand; Debt collection applies.
A7: 8053 | B7: I was shocked when I reviewed my credit report and found late payment on the dates below : XX/XX/2018- 30 DAYS LATE I am not sure how this happened, I believe that I had made my payments to you when I received my statements. My only thought is that my monthly statement did not get to me. | C7: Credit reporting | D7: No card is named; the complaint is explicitly about a late-payment entry on the credit report, so Credit reporting applies.
A8: 8060 | B8: I've recently received a copy of my credit report and noticed several inaccuracies and unauthorized accounts/information reporting to my credit report. These remarks have been detrimental to my life and credit health. CAPIO PARTNERS LLC {$3100.00} XX/XX/year> | C8: Credit reporting
A9: 8062 | B9: I am submitting this complaint regarding Credit Karmas refusal to update my legal name on their platform, despite my repeated efforts and full compliance with their documentation requirements. I legally changed my name and have already updated it with the XXXX XXXX XXXX and on my government-issued ID. I contacted Credit Karma to request that they update my account to reflect my correct legal name. As requested, I submitted a copy of my government-issued ID and Social Security card , both showing my current legal name. Despite providing this documentation, Credit Karma has refused to update my account. Their support team has not given a clear or valid reason for this refusal, nor have they offered any alternative solution. This failure to update my name has caused confusion and concern, especially as Credit Karma continues to pull and report credit information under a name that is no longer legally mine. I am concerned that this may impact the accuracy of my credit file and hinder my ability to manage my financial accounts effectively. I believe I have made every reasonable effort to work with Credit Karma, and I am now requesting assistance from the CFPB to resolve this matter. I am seeking that Credit Karma update my name in their system in accordance with the legal documentation I have provided and that they ensure all associated credit reporting is accurate. | C9: Credit reporting
A10: 8071 | B10: Upon termination of my lease in XXXX I was assessed a disposition fee above the contractual obligation. In investigating this fee I had discovered that XXXX XXXX was charging for hail damage to the vehicle. This vehicle never experienced a hail storm while in my possession. The process of contacting XXXX XXXX XXXX XXXX and disputing the charge took costly time. Once the determination was made by a XXXX representative that I was indeed not responsible for any additional charges, as there was no hail damage, I immediately paid the remaining disposition fee. I had never been late in a vehicle payment to XXXX or any other automotive debtor. Because of the time it took XXXX XXXX to investigate and correct this charge I was outside of my 30 day payment window. They they reported me to the 3 bureaus as having a late payment. I sent my formal request to have the negative marks removed from my credit report at the 3 bureaus ; XXXX, XXXX, and XXXX. I submit this request on authority from the representatives at XXXX. I included a brief statement on what had happened and a copy of my credit report. On XX/XX/XXXX I received a letter from XXXX XXXX saying their reporting was correct. I called on XX/XX/XXXX to take further action. At this point I was informed I could make another formal dispute but could not actually speak with anyone who makes the decisions. A customer service rep by the name of XXXX and his supervisor XXXX were quite unwilling to help. I just want the negative mark removed from my credit. I am currently not obligated with any further debt to XXXX XXXX. | C10: Credit reporting
A11: 8074 | B11: I am writing to request an investigation of the following information that appears on my Early Warning Systems consumer report, which I believe to be fraudulent. In accordance with the Fair Credit Reporting Act, I assert that the list of accounts below has violated my federally protected consumer rights to privacy and confidentiality under 15 USC 1681. These items listed above have violated my rights as outlined in 15 U.S.C. 1681, Section 602 A, which grants me the right to privacy. 15 U.S.C. 1681, Section 604 A, Section 2 also states that a consumer reporting agency can not furnish an account without my written instructions. Furthermore, 15 U.S.C. 1681c ( a ) ( 5 ) stipulates that no consumer reporting agency may include any adverse items on a consumer report if they predate the report by more than seven years. Additionally, 15 U.S.C. 1681s-2 ( a ) ( 1 ) specifies that no information can be furnished to a consumer reporting agency if the person knows, or has reasonable cause to believe, that the information is inaccurate. I have NEVER opened or used the following account numbers, and I request that all information related to these accounts be removed immediately : Bank : XXXX XXXX Incident Date : XX/XX/year> Contribution Ref # : XXXX Account # : XXXX ABA Number # : XXXX Additionally, I do not recognize the following inquiries that appear on my report. I am a victim of identity theft, and I do not recognize the following inquiries. I request that the following inquiries be removed from my Early Warning Services consumer report immediately : | C11: Credit reporting
A12: 8094 | B12: On XX/XX/XXXX an online transaction was made through our banking institution Wells Fargo via XXXX in the amount of {$230.00}. XX/XX/XXXX XXXX TO XXXX XXXX ON XX/XX/XXXX REF # XXXX {$230.00}. The product/service was not received. Contacted Wells Fargo and a claim was filed # XXXX. We would like our money back. This was fraudulent act committed ; Wells Fargo should back all transactions on their website and in good faith refund the customer. We were told most likely we would not be getting our funds back. Please assist in obtaining our {$230.00} back. Thanks. | C12: Money transfer or service
A13: 8095 | B13: On XX/XX/XXXX/XX/XX/XXXX my debit card was stolen while on a work trip in XXXX, New York In addition it was my contention that the thief was able to get my PIN. That thief, used the card throughout the XXXX XXXX XXXX area, charging up almost {$3000.00} dollars at 30 various different drug stores over a 3 hour period, making cash back purchases in small increments on average of {$50.00} dollars. I reported the fraudulent charges to the bank as soon as I became aware, as did my wife who is joint on the account. I filed a police report in XXXX XXXX XXXX and XXXX XXXX, CA, my place of residence. Upon review the bank rescinded the credits to my account and stated their judgement was based upon inconsistencies with my and my wife 's statements. As i mentioned to the back, I was not aware of how it was stolen, but merely giving them suggestions on who might have been the perpetrator. The bank investigators did n't not put forward a good faith effort to follow up on this claim, nor did the bank hold up their fiduciary responsibility to protect my debit card from this clear fraud while it was happening. Furthermore, while I still have an active police investigation, the bank has already rendered judgement. This matter will be resolved in civil court if I ca n't get the protection of the Bank in regards to my FDIC protected money. I wish to report the bank, the claims department and its management for gross negligence in this matter and I hope the CFPB can help me gain protection from a banks disregard for its primarily responsibility to protect my money | C13: Money transfer or service
A14: 8096 | B14: An unauthorized transaction was made on my Chime XXXX XXXX account on XX/XX/year> in the amount of {$1400.00} at XXXX XXXX. I transferred funds to my account to set aside for a moving fund. I filed a dispute with Chime on XX/XX/XXXX they then denied my claim the following day without proper investigation. An appeal or rebuttal was filed on XX/XX/XXXX at which point I also provided a written statement and a statement from the business stating the charge was unauthorized. That rebuttal was also denied despite submitting substantial information. I tried calling police but because I was unsure where I misplaced my credit card they were unwilling to file a dispute. It has been now almost XXXX months of me fighting the bank and nothing has been returned to me and this issue has yet to be resolved. | C14: Money transfer or service
A15: 8097 | B15: I have notified Experian, XXXX and XXXX several times regarding the XXXX XXXX account. XXXX XXXX is refusing to discuss collection for XXXX account or accept any payments from me stating they are no longer handling account it is with a 3rd party. The is no other company reporting this account to my credit report, only XXXX XXXX. I have attempted several times to resolve this account with XXXX XXXX with the latest being today XX/XX/2021 at XXXX eastern, I spoke with XXXX whom once again refuses to discuss account, accept payment or even send a current dated bill for the balance owed. I have recorded conversations of XXXX XXXX refusals. I have filed several disputes advising Experian, XXXX and XXXX of the issues with XXXX XXXX and the recorded conversations with contact information to reach me to hear them. All 3 continue to close my disputes stating they verified account details without investigating the issue Im disputing. XXXX XXXX should not be allowed to remain on my credit report if they are refusing to discuss account, accept payment for account or even send me a current bill for account. At this point Im ready to get a lawyer and sue Experian, XXXX, XXXX and XXXX XXXX because Ive tried for several months to resolve this myself to no avail. | C15: Credit reporting
A16: 8098 | B16: I am submitting this complaint due to a judgment and wage garnishment related to a charged-off XXXX account. I was never properly served with notice of the original lawsuit and only became aware of the judgment after receiving notice that my wages would be garnished. I did not live at the address sworn to be served at. I have attached my lease for the time frame in question. I filed a Motion to Strike the judgment on the grounds of improper service, but it was denied. The debt collector has not provided a valid affidavit or proof of service that complies with state law requirements. I believe this violated my due process rights. Additionally, I never received a proper debt validation or breakdown of the amount allegedly owed. The debt was originally charged off by XXXX, and I do not have confirmation that the current party attempting to collect has the legal right to do so. I am requesting the following from the CFPB : An investigation into whether proper service of process was completed before the judgment was granted. Confirmation that the entity pursuing the garnishment is authorized to collect on this debt. Full validation of the alleged debt, including the original contract, chain of assignment, and accounting of charges. I believe this judgment and garnishment may have been obtained unlawfully and am requesting assistance in having it vacated if violations occurred. Thank you for your attention to this matter. | C16: Debt collection
A17: 8106 | B17: My mortgage loan originated XX/XX/XXXX. In XXXX, I applied for a home made affordable loan modification but was denied. Wells Fargo informed me that I could do a short sale. My realtor submitted several offers to them for a short sale and they refused them and proceeded to foreclose on the property in XX/XX/XXXX. On XX/XX/XXXX, I contacted Wells Fargo 's Enterprise Complaints Mgmt Office letting them know that I felt my home had been wrongfully foreclosed and was given a case number and assigned a representative. XXXX XXXX is my Case SpecialistXXXX XXXX XXXXXXXX. I have received four different letters stating they need more time to finalize their research. I feel they are are not taking the situation seriously. I was told that another letter is in the mail stating that they should complete their work by XX/XX/XXXX. That will be two months from the date that I reached out to them. | C17: Mortgage
A18: 8108 | B18: I last spoke with a supervisor ( XXXX ) on XXXX after receiving the last response from a Citibank Representative on my recent complaint with CFPB. Although, I did not inquire about " settling '' the account I was not given any options on how to resolve the balance either. Currently, the principal balance according to XXXX is {$590.00} with {$170.00} ( late fees of {$25.00} per month ) plus any interest. Prior to the conversation with XXXX, a conversation ( early XXXX ) with a representative in the loan department stated that " for two payments ( XXXX and XXXX ) no interest would be charged and the account would be deferred. '' I would not need to make any payments. But, I made a payment in XXXX in the amount of {$250.00} ( {$220.00} is the minimum payment ). XXXX refused to provide any options on how to resolve the matter. I asked about waiving a few fees, to which were immediately dismissed by saying '' we can't do that because you were consistently late. '' Which I felt was extremely offensive, I felt like a criminal in that moment. In XXXX of last year, I lost my job which put me behind in payments. But I paid what I could. Now I am a product of the Pandemic, but I am still paying trying to resolve this responsibility. I was so angry by her statement that I responded back stating " I could easily let the account go and not pay anything! '' My experience with Citibank has been an extremely horrible ordeal. It is unfortunate that I stayed this long, over 10 years. | C18: Consumer loan | D18: Loan type is not named; using Consumer loan as the standing generic-loan tie-break.
A19: 8118 | B19: I am filling a complaint against Cash App ( Block INC. ) due to inadequate customer service and unfair practices, which violate the Consumer Financial Protection Act. Specifically, Cash App failed to take timely and effective measures to prevent and address fraud on their platform, leaving my account vulnerable and unprotected. Furthermore, their dispute resolution process was unfair and deceptive, as they did not comply with Electronic Fund Transfer Act and Regulation E. These actions have caused significant inconvenience and financial loss and i seek appropriate redress for these violations | C19: Money transfer or service
A20: 8122 | B20: I am filing this complaint regarding a medical collection account being reported on my consumer credit reports by Aargon Agency , Inc . This account is inaccurate, unlawfully reported, and should be immediately deleted for the reasons outlined below. First, I never authorized the original medical provider or any third party to disclose my protected health information ( PHI ) to this collection agency for the purpose of credit reporting. The reporting and furnishing of this account necessarily involves the disclosure of sensitive medical information, which I did not consent to. This appears to be a violation of the Health Insurance Portability and Accountability Act ( HIPAA ) and its privacy protections regarding unauthorized disclosure of medical information. Second, this account has been reported to the consumer reporting agencies without proper validation and without a permissible purpose, in violation of the Fair Credit Reporting Act ( 15 U.S.C. 1681 et seq. ). I dispute the accuracy, ownership, and legal authority of this collection account. The furnisher has failed to demonstrate that it has the legal right to report this alleged debt or that the information being reported is complete and accurate. Additionally, medical collections are subject to heightened accuracy and privacy requirements. The continued reporting of this account is causing ongoing harm to my credit profile and financial well-being. I am requesting that the CFPB require Aargon Agency, Inc to : Immediately delete this medical collection account from all consumer reporting agencies Cease any further reporting or disclosure of my medical information Provide written confirmation that this account has been permanently removed If this matter is not resolved promptly, I reserve all rights to pursue further complaints with the Office for Civil Rights ( OCR ) for HIPAA violations and any additional legal remedies available to me. | C20: Credit reporting | D20: Both collection and reporting language appear, but the requested remedy is deletion of an inaccurately reported collection tradeline; Credit reporting.
A21: 8125 | B21: The company currently servicing our mortgage reached out in XX/XX/XXXX to refinance our mortgage due to the low rates, so we agreed. We locked in a rate of 3.125 % on XX/XX/XXXX with NewRez and supplied them with all the upfront requested documentation and eSigned all necessary forms. It is now XX/XX/XXXX and we still have NOT closed on the refinanced loan and they are asking for more documents, and my husband to correct the figures multiple times on the documents provided by NewRez for the refinance ( incorrect escrow figure, property taxes, etc. ). We constantly reached out to the company throughout the multitude of months since starting the process in XXXX and were told various stories about how the loan would be underwriting soon once one more bit of information was verified -- and the information to be verified never was accurate to begin with for our loan. Or, there would be no response and no escalation even after we demanded status updates with set deadline dates for such information. We have lost out on four months of saving {$300.00} a month that the refinance should have secured had it closed at the end of XX/XX/XXXX as it should have closed, and we now can not refinance with an alternate company at the same rate as rates have now increased, and also, the loan office does not get paid until this loan closes so there are multiple parties effected by this company 's gross incompetence. | C21: Mortgage
A22: 8128 | B22: Kia Motor Finance has a deferment program which I applied for and instead of them trying to help me they refuse to - my loan will be 60 days late by the XXXX of this month and they will not help - they say they will approve you and then tell you that there is a document that you need to sign and send back however in the meantime they do not sent the document and this will impact my credit - they are not being helpful at all. | C22: Consumer loan | D22: The product is an auto loan from Kia Motor Finance; Consumer loan applies.
A23: 8129 | B23: Have filed multiple different disputes with Equifax for an account on my credit with XXXX XXXX XXXX that was opened under fraud. Each time there is no resolution, the account continues to show up on my report causing me to lose time by filing disputes and delay any credit related purchases that I may have. XXXX and XXXX have both already removed the account without delay. Complaints have already been filed with the FTC and Equifax still will not take action. | C23: Credit reporting
A24: 8130 | B24: I am stressed out because this company is violating my rights Under 15 U.S.C. 1681s-2 ( a ), data furnishers are required to report only accurate and complete information.Reporting unverifiable or inaccurate data is a violation of federal law. | C24: Credit reporting
A25: 8136 | B25: I did apply for the card but never finalized that I wanted because it was only for {$300.00} and they take {$80.00} of that for fees etc so I didn't want it and never confirmed that I wanted the credit card ... I don't even have the card in my possession... | C25: Credit card
A26: 8142 | B26: I attempted to withdraw money from my account to another bank account in my name. Marcus froze the funds and claimed that they needed onerous documentation from me ( a statement from my other bank sent to them via mail ) in order to complete the transfer. They also could not manually reverse the transfer, leaving my $ XXXX in limbo while Marcus decides what to do with the funds at their sole discretion. | C26: Money transfer or service
A27: 8166 | B27: I sold an item and shipped it via USPS Media Mail to a buyer named XXXX XXXX. She filed a PayPal dispute claiming she never received the package. This was false. She refused delivery and had the package returned to sender. I have the returned package in hand with a USPS label clearly marked " Return Postage Due = {$5.00} '' dated XX/XX/year> and stamped " Refused. '' Despite my evidence, PayPal ruled in her favor. The fraudulent dispute resulted in a {$19.00} reversal against me, plus I was charged {$5.00} in return postage caused directly by her refusal. Total loss : {$24.00}. I am requesting PayPal reopen and reverse this decision. | C27: Money transfer or service
A28: 8168 | B28: The credit bureaus must obey many laws, including the Fair Credit Reporting Act ( FCRA ). And according to the FCRA insert condition such as an incorrect balance an incorrect account number an undated late pay a missing field of missing field here such as status the wrong account type an incorrect a late pay after account was closed an inaccurate date of last activity an inaccurate date of last update a charge off listed as open a collection account with an inaccurate reporting dateLEAD BANK self XXXX POTENTIALLY NEGATIVE MONTHS Credit usage 0 % account Balance updated XXXX XXXX, XXXX Credit limit {$1000.00} Account info Account number XXXX Open/closed Closed Date opened XX/XX/XXXX Account type Revolving PAID CHARGE OFF VARIABLE RATE. PAID CHARGE OFF VARIABLE RATE. XXXX # XXXX Open/closed Closed Date opened XX/XX/XXXX Account type, Account, XXXX, XXXX Installment reported late payment XX/XX/XXXX XXXX XXXX XXXX XXXX PAYMENT Balance {$0.00} Balance updated XX/XX/XXXX, | C28: Credit reporting
A29: 8174 | B29: Our mortgage company 's loss/draft department are solely to blame for our issue. Not the insurance company or the VA. We had a catastrophic loss of our home and we have cooperated with everything they have asked, but they do not give us the funds we need and have paid out of pocket and taken from our retirement savings, at a heavy tax levied against us, and our personal savings. We had difficulty getting a contractor to over see the work. Our last contractor did nothing for 8 months. Nothing. So we became our own general contractor and got our permits and hired the sub contractors. I am attaching some of the emails we have written. So far we have asked for reimbursement from two contractors for the final completion of the exterior of the house and the excavation company that worked to remove the old burned house and dig/fill utility trenches, and prepare the ground for radon barrier and concrete pour. They did reimburse at least once for our underground plumbing work and the builder completing the outer shell of the house. We have been waiting for 4 weeks for them to pay the final bill to that company. | C29: Mortgage
A30: 8180 | B30: Subject : Repeated Account Closures After Approval Request for Explanation I am submitting this complaint regarding a pattern of behavior by Capital One that I believe may constitute an unfair or deceptive practice. Capital One has repeatedly approved my applications for credit cards, only to close the accounts shortly afterward citing a vague business decision without providing any meaningful explanation. This has occurred multiple times. Despite these closures, Capital One continues to solicit and approve new credit card applications for me. This creates a confusing and frustrating situation where I am led to believe I am eligible for their products, only to have the accounts closed again shortly after opening. I have no negative payment history with Capital One and have complied with all account terms. Because these approvals are being granted and then reversed repeatedly, I am concerned that this process may result in unnecessary hard inquiries on my credit report and, in some cases, the collection of annual fees before the account is closed. At this point, I am requesting that Capital One provide a clear explanation addressing the following : 1. Why my accounts continue to be approved and then closed shortly thereafter. 2. Whether I am internally flagged or otherwise deemed ineligible for Capital One credit products. 3. Why I continue to receive solicitations and approvals if the bank has no intention of maintaining a credit relationship with me. If Capital One has determined that I am not eligible for their products, I respectfully request that they cease marketing and approving applications for credit cards in my name. I am simply seeking transparency and fair treatment in this matter. Thank you for your attention to this issue. | C30: Credit card
A31: 8184 | B31: I have a a few loans with RISE. Last month when I looked at my credit report I had XXXX inquiry from this company now I have XXXX and they all are dated for different months in the same year. I understand that the company will pull my credit to approve the loan, but they can not place the inquires on the file 10mos after the loan has been paid off. | C31: Credit reporting | D31: Loan type is not named, but the complaint is about credit-report inquiries; reporting is the subject under the Protocol.
A32: 8203 | B32: I am filing a complaint against Cash app ( Block, Inc. ) due to inadequate customer service and unfair practices, which violate the Consumer Financial Protection Act ( CFPA ). Specifically, Cash App failed to take timely and effective measures to prevent and address fraud on their platform, leaving my account vulnerable and unprotected. Furthermore, their dispute resolution process was unfair and deceptive, as they did not comply with error resolution requirements under the Electronic Fund Transfer Act ( EFTA ) and Regulation E. These actions have caused significant inconvenience and financial loss, and I seek appropriate redress for these violations. | C32: Money transfer or service
A33: 8206 | B33: In XX/XX/2021, our mortgage payment was {$1500.00} instead of the normal {$1100.00}. I paid it and thought it was the difference for insurance. XXXX came around and it was high again. After tons of call and inquiring, they filed my property tax incorrectly. I got the necessary paperwork to them. They told us to use the 15 day grace period to allow them to correct the numbers and pay our mortgage. They say we will owe {$1500.00} this month. We should get a lower payment plus last months overpayment reimbursement. Ive called 29 times. Ive been told to shut up, Ive been hung up on 5 times. I get told different things every time. No one knows what to do or how to help. They just say pay the {$1500.00} and they will fix it. I need to know what happened to the {$600.00} escrow check they sent out, when it will be fixed, and to be certain it wont reflect on my credit score. Most unprofessional company Ive ever experienced. | C33: Mortgage
A34: 8207 | B34: Money was XXXX or XXXX from XXXX XX/XX/XXXXXXXX where I received my Direct Deposit Payroll, to XXXX XXXX XXXX XXXX XX/XX/XXXX The intent was to buy some shares of XXXX, since they are a Stock/Trading company. My deposit is not there. They can't find it. Initially I was given an availability date of XX/XX/XXXX then 2 days later it was changed to XX/XX/XXXX, which I clutched my pearls, and thought that was kinda a long time to hold one 's funds! : ( Why did the dates change twice, & now my funds are " stuck '' somewhere, waiting to be processed!? Chime says the didn't receive the REJECTED funds back yet that XXXX admitted to rejecting. I talked to a Gentleman named XXXX at XXXX who explained this unfortunate latest update to me! | C34: Money transfer or service
A35: 8213 | B35: I have a loan with United Wholesale Mortgage. I have not been able to reach ANYONE from customer service I had an insurance rep call me with the same problem trying to reach them They do not answer the phone and do not acknowledge even having my loan, and however long i try or whatever phone number i try reaching customer service on it just does not go through. | C35: Mortgage
A36: 8215 | B36: I have submitted multiple disputes regarding these accounts that is reporting inaccurately on my credit report. I have also submitted multiple reports regarding the account that needs to be updated These companies have refused to do work on disputes even though they're required by the law to do so. Account Name : XXXX | C36: Credit reporting | D36: No card is named; the complaint is explicitly about inaccurate reporting and disputes on the credit report.
A37: 8222 | B37: I received an email that my account was closed at XXXXXXXX XXXX XXXX on XX/XX/year>, with no stated reason. Since this email, my account is restricted and I am unable to access {$3300.00} in my account. | C37: Bank account or service | D37: Account type is not specified; closest fit is Bank account or service because the complaint is account restriction and inability to access the balance.
A38: 8225 | B38: XXXX & Equifax are reporting an erroneous collection on my credit report for XXXX XXXX XXXX - XXXX - I never received one notice regarding this debt, it just showed up on my credit report. This was paid | C38: Credit reporting
A39: 8244 | B39: According to 15 use 1681eb Everything must be 100 percent max accurate The credit bureaus keep disrespecting the laws. I showed them multiple times of how they are violating the Fair Credit Reporting Act. According to 15 use 1681 ( 5 ) The credit bureaus said everything was complete and accurate and I asked them how if the open date is wrong. Then I ask them to provide me description of the investigation according to 15 USC 1681 ( 7 ) and they never did. I have proof of my letter for that. Also according to 15 USC 1681 s-2 A person shall not furnish any information relating to a consumer to any consumer reporting agency if the person knows or has reasonable cause to believe that the information is inaccurate. This is violation after violation after violation. This is causing me stress because I have no hope with this system | C39: Credit reporting
A40: 8245 | B40: I am writing to formally contest the inclusion of fraudulent account in my Experian credit report. Despite submitting a dispute letters and the required documentation to the Federal Trade Commission ( FTC ), as per your guidelines, this account persist on my Experian report. After uncovering this fraudulent account, I contacted the relevant bank, which acknowledged its fraudulent nature and assured me of its removal from their records. Subsequently, XXXX and XXXX have both expunged this account from their records after verifying its fraudulent status. I am puzzled as to why Experian continues to report this fraudulent account, especially since the other credit bureaus have already removed it. I have completed all necessary steps and furnished all relevant documentation to substantiate my claim of identity theft. I hereby request a comprehensive investigation into this matter and the immediate removal of this fraudulent accounts from my Experian credit report. The bank has confirmed the fraudulent nature of this account, and its persistence on my credit report is unjustified and detrimental to my creditworthiness. XXXX XXXX XXXX XXXX XXXX XXXX XXXX XXXX XXXX XXXX XXXX | C40: Credit reporting
...

Sheet Labeler 2
A1: row_id | B1: narrative | C1: your_category | D1: flag_note (if forced/hard fit/general comments)
A2: 8022 | B2: I applied for a bank account with XXXX on XXXX XXXX and was declined stating there were discrepancies on my XXXX report. I knew that had to be an error because i filed for bankruptcy and every creditor was ordered by the judge to CEASE AND DESIST. I filed chapter XXXX bankruptcy with case XXXX FL on XX/XX/17 and the case was discharged in XX/XX/2017. However, XXXX XXXX is STILL REPORTING EVEN AFTER MY BANKRUPTCY. Each creditor is subject to up to {$1000.00} fine for violation of fair credit reporting act. Chapter XXXX bankruptcy discharges all debt! | C2: Credit reporting | D2: Bank account denial is the trigger, but complaint is post-bankruptcy reporting
A3: 8024 | B3: I fell victim to a multilayered scam operation orchestrated by XXXX ( XXXX ) ( the Company ) with the design, development, manufacturing, promoting, marketing, distributing, labeling, and/or sale of illegal and outright fraudulent investment services, all of which aim at contributing to the goal of robbing and defrauding clients through a predetermined cycle of client losses to gains in the equivalent of XXXX USD which was transferred from my wallet utilizing Coinbases services. | C3: Money transfer or service
